Hi Team,

We are able to launch Jupyter session with python version 3.7 So it looks like only with python 3.8 we are getting a timeout.


Regards,
Pete